[2017-11-02 08:57:30] Starting Scheduler
[2017-11-03 00:00:00] Running Job
2017-11-03 00:00:00 | Starting Fetch | Eculum_ai
2017-11-03 00:00:00 | Starting Fetch | TheSumanJha
2017-11-03 00:00:00 | Starting Fetch | Manveer61503354
2017-11-03 00:00:01 | Starting Fetch | paraaZz
2017-11-03 00:00:01 | Starting Fetch | arorakanav11
2017-11-03 00:00:01 | Starting Fetch | bansaladitya209
2017-11-03 00:00:02 | Starting Fetch | Pareekshit16
2017-11-03 00:00:02 | Starting Fetch | SwastikaaSharma
2017-11-03 00:00:03 | Starting Fetch | JaskaranSingh_1
2017-11-03 00:00:03 | Starting Fetch | seishan_
2017-11-03 00:00:04 | Saving Data | paraaZz
2017-11-03 00:00:04 | Time Taken | 2.43
2017-11-03 00:00:04 | Saving Data | JaskaranSingh_1
2017-11-03 00:00:04 | Time Taken | 0.69
2017-11-03 00:00:04 | Saving Data | seishan_
2017-11-03 00:00:04 | Time Taken | 0.27
2017-11-03 00:00:17 | Saving Data | TheSumanJha
2017-11-03 00:00:17 | Time Taken | 16.81
Error: Unable to connect to the server, please try again later.
2017-11-03 00:01:48 | Saving Data | Manveer61503354
2017-11-03 00:01:48 | Time Taken | 107.18
Error: Unable to connect to the server, please try again later.
2017-11-03 00:01:48 | Saving Data | Pareekshit16
2017-11-03 00:01:48 | Time Taken | 105.55
Error: Unable to connect to the server, please try again later.
2017-11-03 00:01:49 | Saving Data | arorakanav11
2017-11-03 00:01:49 | Time Taken | 107.25
Error: Unable to connect to the server, please try again later.
2017-11-03 00:01:49 | Saving Data | SwastikaaSharma
2017-11-03 00:01:49 | Time Taken | 106.47
Error: Unable to connect to the server, please try again later.
2017-11-03 00:01:50 | Saving Data | bansaladitya209
2017-11-03 00:01:50 | Time Taken | 108.08
Error: Unable to connect to the server, please try again later.
2017-11-03 00:01:50 | Saving Data | Eculum_ai
2017-11-03 00:01:50 | Time Taken | 110.42
Error: Unable to connect to the server, please try again later.
Traceback (most recent call last):
  File "clock.py", line 1, in <module>
    from common.config import *
  File "/root/eculum-main-jobs/common/config.py", line 4, in <module>
    CONSUMER_KEY  = os.environ['CONSUMER_KEY']
  File "/usr/lib/python3.5/os.py", line 725, in __getitem__
    raise KeyError(key) from None
KeyError: 'CONSUMER_KEY'
Traceback (most recent call last):
  File "clock.py", line 2, in <module>
    import jobs as jobs
  File "/root/eculum-main-jobs/jobs/__init__.py", line 1, in <module>
    from jobs.tw_analyse import TwAnalyse
  File "/root/eculum-main-jobs/jobs/tw_analyse.py", line 99
    while 1:
           ^
TabError: inconsistent use of tabs and spaces in indentation
